<?xml version="1.0"?>
<sdf version="1.9">
  <model name="spiri_gimbal">
    <pose>0 0 0 0 0 0</pose>
    <link name="base_link">
      <inertial>
        <mass>0.2</mass>
        <inertia>
          <ixx>0.0001</ixx>
          <ixy>0</ixy>
          <ixz>0</ixz>
          <iyy>0.0001</iyy>
          <iyz>0</iyz>
          <izz>0.0001</izz>
        </inertia>
      </inertial>
      <visual name="base_visual">
        <geometry>
          <mesh>
          <scale>0.01 0.01 0.01</scale>
            <uri>model://robots/spiri_mu/models/spiri_gimbal/meshes/mu2_gimbal_base.fbx</uri>
          </mesh>
        </geometry>
        <material>
          <ambient>0.1 0.1 0.1</ambient>
          <diffuse>0.1 0.1 0.1</diffuse>
          <specular>1 1 1 0</specular>
        </material>
      </visual>
      <collision name="base_collision">
        <pose>0 0 0 0 0 0</pose>
        <geometry>
          <mesh>
            <scale>0.01 0.01 0.01</scale>
            <uri>model://robots/spiri_mu/models/spiri_gimbal/meshes/mu2_gimbal_base.fbx</uri>
          </mesh>
        </geometry>
      </collision>
    </link>

    <link name="yaw_link">
      <pose>0 0 -0.0223 0 0 0</pose>
      <inertial>
        <mass>0.01</mass>
        <inertia>
          <ixx>0.00001</ixx>
          <ixy>0</ixy>
          <ixz>0</ixz>
          <iyy>0.00001</iyy>
          <iyz>0</iyz>
          <izz>0.00001</izz>
        </inertia>
      </inertial>
      <visual name="yaw_visual">
        <geometry>
          <mesh>
            <scale>0.01 0.01 0.01</scale>
            <uri>model://robots/spiri_mu/models/spiri_gimbal/meshes/mu2_gimbal_yaw.fbx</uri>
          </mesh>
        </geometry>
        <material>
          <ambient>0.1 0.1 0.1</ambient>
          <diffuse>0.1 0.1 0.1</diffuse>
          <specular>1 1 1 0</specular>
        </material>
      </visual>
      <collision name="yaw_collision">
        <geometry>
          <mesh>
            <scale>0.01 0.01 0.01</scale>
            <uri>model://robots/spiri_mu/models/spiri_gimbal/meshes/mu2_gimbal_yaw.fbx</uri>
          </mesh>
        </geometry>
      </collision>
    </link>
    <joint name="yaw_joint" type="revolute">
      <parent>base_link</parent>
      <child>yaw_link</child>
      <axis>
        <xyz>0 0 1</xyz>
        <dynamics>
          <damping>0.01</damping>
        </dynamics>
        <limit>
          <lower>-2.356194</lower>
          <upper>2.356194</upper>
        </limit>
      </axis>
    </joint>
  
    <link name="roll_link">
      <pose frame=''> 0 0.02148 -0.0579 0 0 0 </pose>
      <inertial>
        <mass>0.01</mass>
        <inertia>
          <ixx>0.00001</ixx>
          <ixy>0</ixy>
          <ixz>0</ixz>
          <iyy>0.00001</iyy>
          <iyz>0</iyz>
          <izz>0.00001</izz>
        </inertia>
      </inertial>
      <visual name="roll_visual">
        <geometry>
          <mesh>
            <scale>0.01 0.01 0.01</scale>
            <uri>model://robots/spiri_mu/models/spiri_gimbal/meshes/mu2_gimbal_roll.fbx</uri>
          </mesh>
        </geometry>
        <material>
          <ambient>0.1 0.1 0.1</ambient>
          <diffuse>0.1 0.1 0.1</diffuse>
          <specular>1 1 1 0</specular>
        </material>
      </visual>
    </link>
    <joint name="roll_joint" type="revolute">
      <parent>yaw_link</parent>
      <child>roll_link</child>
      <axis>
        <xyz>0 1 0</xyz>
        <dynamics>
          <damping>0.01</damping>
        </dynamics>
        <limit>
          <lower>-1.570796</lower>
          <upper>1.570796</upper>
        </limit>
      </axis>
    </joint>
    
    <link name="pitch_link">
      <pose frame=''> -0.020 -0.0086 -0.0579 0 0 0</pose>
      <inertial>
        <mass>0.01</mass>
        <inertia>
          <ixx>0.00001</ixx>
          <ixy>0</ixy>
          <ixz>0</ixz>
          <iyy>0.00001</iyy>
          <iyz>0</iyz>
          <izz>0.00001</izz>
        </inertia>
      </inertial>
      <visual name="pitch_visual">
        <geometry>
          <mesh>
            <scale>0.01 0.01 0.01</scale>
            <uri>model://robots/spiri_mu/models/spiri_gimbal/meshes/mu2_gimbal_pitch.fbx</uri>
          </mesh>
        </geometry>
        <material>
          <ambient>0.1 0.1 0.1</ambient>
          <diffuse>0.1 0.1 0.1</diffuse>
          <specular>1 1 1 0</specular>
        </material>
      </visual>
      <sensor name="camera" type="camera">
        <pose degrees="true">0 0 0 0 0 -90</pose>    
        <camera>
          <horizontal_fov>2.0</horizontal_fov>
          <image>
            <width>640</width>
            <height>480</height>
          </image>
          <clip>
            <near>0.05</near>
            <far>15000</far>
          </clip>
        </camera>
        <always_on>1</always_on>
        <update_rate>10</update_rate>
        <visualize>1</visualize>

        <plugin filename="CameraZoomPlugin"
            name="CameraZoomPlugin">
          <max_zoom>125.0</max_zoom>
          <slew_rate>0.42514285714</slew_rate>
        </plugin>
        
        <plugin name="GstCameraPlugin"
            filename="GstCameraPlugin">
          <udp_host>127.0.0.1</udp_host>
          <udp_port>5600</udp_port>
          <use_basic_pipeline>true</use_basic_pipeline>
          <use_cuda>false</use_cuda>
        </plugin>

      </sensor>
    </link>
    <joint name="pitch_joint" type="revolute">
      <parent>roll_link</parent>
      <child>pitch_link</child>
      <axis>
        <xyz>1 0 0</xyz>
        <dynamics>
          <damping>0.01</damping>
        </dynamics>
        <limit>
          <lower>-2.356194</lower>
          <upper>2.356194</upper>
        </limit>
      </axis>
    </joint>

  </model>
</sdf>
